<?xml version="1.0"?>
<robot name="pegasus_arm">

  <!-- =========================
       1) Base Link
       ========================= -->
  <link name="base_link">
    <inertial>
      <mass value="0.3"/>
      <origin xyz="0 0 0" rpy="0 0 0"/>
      <inertia ixx="1.2e-4" ixy="0" ixz="0" iyy="1.2e-4" iyz="0" izz="1.2e-4"/>
    </inertial>

    <!-- Visual Geometry -->
    <visual>
      <origin xyz="0 0 0" rpy="0 0 0"/>
      <geometry>
        <cylinder radius="0.1" length="0.05"/>
      </geometry>
      <material name="black">
        <color rgba="0 0 0 1"/>
      </material>
    </visual>

    <!-- Collision Geometry -->
    <collision>
      <origin xyz="0 0 0" rpy="0 0 0"/>
      <geometry>
        <cylinder radius="0.1" length="0.05"/>
      </geometry>
    </collision>
  </link>

  <!-- =========================
       Joint 1 (Base) - Continuous
       ========================= -->
  <joint name="joint1_base" type="continuous">
    <origin xyz="0 0 0.05" rpy="0 0 0"/>
    <parent link="base_link"/>
    <child link="link1"/>
    <axis xyz="0 0 1"/>
    <initial_position value="0.00"/>
  </joint>

  <!-- =========================
       Link 1
       ========================= -->
  <link name="link1">
    <inertial>
      <mass value="0.3"/>
      <origin xyz="0 0 0" rpy="0 0 0"/>
      <inertia ixx="1.2e-4" ixy="0" ixz="0" iyy="1.2e-4" iyz="0" izz="1.2e-4"/>
    </inertial>

    <!-- Visual Geometry -->
    <visual>
      <origin xyz="0 0 0" rpy="0 0 0"/>
      <geometry>
        <cylinder radius="0.1" length="0.05"/>
      </geometry>
      <material name="blue">
        <color rgba="0.0 0.0 1.0 1.0"/>
      </material>
    </visual>

    <!-- Collision Geometry -->
    <collision>
      <origin xyz="0 0 0" rpy="0 0 0"/>
      <geometry>
        <cylinder radius="0.1" length="0.05"/>
      </geometry>
    </collision>
  </link>

  <!-- =========================
       Joint 2 (Shoulder)
       ========================= -->
  <joint name="joint2_shoulder" type="revolute">
    <origin xyz="0 0 0.05" rpy="0 0 0"/>
    <parent link="link1"/>
    <child link="link2"/>
    <axis xyz="0 1 0"/>
    <limit lower="-1.22173" upper="0.610865" effort="10" velocity="1.0"/>
    <initial_position value="-0.726"/>
  </joint>

  <!-- =========================
       Link 2
       ========================= -->
  <link name="link2">
    <inertial>
      <mass value="0.15"/>
      <origin xyz="0 0 0" rpy="0 0 0"/>
      <inertia ixx="1.2e-4" ixy="0" ixz="0" iyy="1.2e-4" iyz="0" izz="1.2e-4"/>
    </inertial>

    <!-- Visual Geometry -->
    <visual>
      <origin xyz="0.1 0.05 0" rpy="0 0 0"/>
      <geometry>
        <box size="0.3 0.05 0.05"/>
      </geometry>
      <material name="yellow">
        <color rgba="1.0 1.0 0.0 1.0"/>
      </material>
    </visual>

    <!-- Collision Geometry -->
    <collision>
      <origin xyz="0.1 0.05 0" rpy="0 0 0"/>
      <geometry>
        <box size="0.3 0.05 0.05"/>
      </geometry>
    </collision>
  </link>

  <!-- =========================
       Joint 3 (Elbow) - 100°
       ========================= -->
  <joint name="joint3_elbow" type="revolute">
    <origin xyz="0.2 0 0" rpy="0 0 0"/>
    <parent link="link2"/>
    <child link="link3"/>
    <axis xyz="0 1 0"/>
    <limit lower="-2.7453296096" upper="1.0" effort="10" velocity="1.0"/>
    <initial_position value="-1.247"/>
  </joint>

  <!-- =========================
       Link 3
       ========================= -->
  <link name="link3">
    <inertial>
      <mass value="0.15"/>
      <origin xyz="0 0 0" rpy="0 0 0"/>
      <inertia ixx="1.2e-4" ixy="0" ixz="0" iyy="1.2e-4" iyz="0" izz="1.2e-4"/>
    </inertial>

    <!-- Visual Geometry -->
    <visual>
      <origin xyz="0.1 0 0" rpy="0 0 0"/>
      <geometry>
        <box size="0.2 0.05 0.05"/>
      </geometry>
      <material name="green">
        <color rgba="0.0 1.0 0.0 1.0"/>
      </material>
    </visual>

    <!-- Collision Geometry -->
    <collision>
      <origin xyz="0.1 0 0" rpy="0 0 0"/>
      <geometry>
        <box size="0.2 0.05 0.05"/>
      </geometry>
    </collision>
  </link>

  <!-- =========================
       Joint 4 - 75°
       ========================= -->
  <joint name="joint4" type="revolute">
    <origin xyz="0.2 0 0" rpy="0 0 0"/>
    <parent link="link3"/>
    <child link="link4"/>
    <axis xyz="0 1 0"/>
    <limit lower="-1.309" upper="0" effort="10" velocity="1.0"/>
    <initial_position value="-1.309"/>
  </joint>

  <!-- =========================
       Link 4
       ========================= -->
  <link name="link4">
    <inertial>
      <mass value="0.15"/>
      <origin xyz="0 0 0" rpy="0 0 0"/>
      <inertia ixx="1.2e-4" ixy="0" ixz="0" iyy="1.2e-4" iyz="0" izz="1.2e-4"/>
    </inertial>

    <!-- Visual Geometry -->
    <visual>
      <origin xyz="0.1 0 0" rpy="0 0 0"/>
      <geometry>
        <box size="0.2 0.05 0.05"/>
      </geometry>
      <material name="red">
        <color rgba="1.0 0.0 0.0 1.0"/>
      </material>
    </visual>

    <!-- Collision Geometry -->
    <collision>
      <origin xyz="0.1 0 0" rpy="0 0 0"/>
      <geometry>
        <box size="0.2 0.05 0.05"/>
      </geometry>
    </collision>
  </link>

  <!-- =========================
       Joint 5 (Wrist) - 360°
       ========================= -->
  <joint name="joint5_wrist" type="continuous">
    <origin xyz="0.2 0 0" rpy="0 0 0"/>
    <parent link="link4"/>
    <child link="link5"/>
    <axis xyz="1 0 0"/>
    <initial_position value="0.00"/>
  </joint>

  <!-- =========================
       Link 5 (End Effector)
       ========================= -->
  <link name="link5">
    <inertial>
      <mass value="0.2"/>
      <origin xyz="0 0 0" rpy="0 0 0"/>
      <inertia ixx="1.2e-4" ixy="0" ixz="0" iyy="1.2e-4" iyz="0" izz="1.2e-4"/>
    </inertial>

    <!-- Visual Geometry -->
    <visual>
      <origin xyz="0 0 0" rpy="0 0 0"/>
      <geometry>
        <sphere radius="0.05"/>
      </geometry>
      <material name="white">
        <color rgba="1.0 1.0 1.0 1.0"/>
      </material>
    </visual>

    <!-- Collision Geometry -->
    <collision>
      <origin xyz="0 0 0" rpy="0 0 0"/>
      <geometry>
        <sphere radius="0.05"/>
      </geometry>
    </collision>

    <!-- Gripper Geometry -->
    <visual>
      <origin xyz="0.1 0 0" rpy="0 0 0"/>
      <geometry>
        <box size="0.1 0.02 0.02"/>
      </geometry>
      <material name="gray">
        <color rgba="0.5 0.5 0.5 1.0"/>
      </material>
    </visual>
    <collision>
      <origin xyz="0.1 0 0" rpy="0 0 0"/>
      <geometry>
        <box size="0.1 0.02 0.02"/>
      </geometry>
    </collision>
  </link>

  <!-- =========================
       Joint 6 (End Effector Alias)
       ========================= -->
  <joint name="joint6_end_effector" type="fixed">
    <origin xyz="0 0 0" rpy="0 0 0"/>
    <parent link="link5"/>
    <child link="end_effector_link"/>
  </joint>

  <!-- =========================
       End Effector Link
       ========================= -->
  <link name="end_effector_link">
    <!-- No additional properties needed as it is an alias -->
  </link>

</robot>

