<?xml version="1.0"?>
<robot name="pegasus" xmlns:xacro="http://www.ros.org/wiki/xacro">

  <!-- World Link (required for world_to_base_joint) -->
  <link name="world"/>

  <!-- Base Link - Base mechanism with internal spur gear -->
  <link name="base_link">
    <visual>
      <geometry>
        <cylinder radius="0.15" length="0.12"/>
      </geometry>
      <origin xyz="0 0 0.06" rpy="0 0 0"/>
    </visual>
    <collision>
      <geometry>
        <cylinder radius="0.15" length="0.12"/>
      </geometry>
      <origin xyz="0 0 0.06" rpy="0 0 0"/>
    </collision>
    <inertial>
      <origin xyz="0 0 0.06" rpy="0 0 0"/>
      <mass value="2.0"/>
      <inertia ixx="0.02" ixy="0" ixz="0" iyy="0.02" iyz="0" izz="0.035"/>
    </inertial>
  </link>

  <!-- Link 1 - Base upper part (Joint 5 in report - Base rotation) -->
  <link name="link1">
    <visual>
      <geometry><box size="0.12 0.12 0.08"/></geometry>
      <origin xyz="0 0 0.04" rpy="0 0 0"/>
    </visual>
    <collision>
      <geometry><box size="0.12 0.12 0.08"/></geometry>
      <origin xyz="0 0 0.04" rpy="0 0 0"/>
    </collision>
    <inertial>
      <origin xyz="0 0 0.04" rpy="0 0 0"/>
      <mass value="0.8"/>
      <inertia ixx="0.008" ixy="0" ixz="0" iyy="0.008" iyz="0" izz="0.012"/>
    </inertial>
  </link>

  <!-- Link 2 - Shoulder link (Joint 4 in report - Shoulder joint with 2 motors) -->
  <link name="link2">
    <visual>
      <geometry><box size="0.25 0.08 0.06"/></geometry>
      <origin xyz="0.125 0 0" rpy="0 0 0"/>
    </visual>
    <collision>
      <geometry><box size="0.25 0.08 0.06"/></geometry>
      <origin xyz="0.125 0 0" rpy="0 0 0"/>
    </collision>
    <inertial>
      <origin xyz="0.125 0 0" rpy="0 0 0"/>
      <mass value="0.7"/>
      <inertia ixx="0.005" ixy="0" ixz="0" iyy="0.015" iyz="0" izz="0.018"/>
    </inertial>
  </link>

  <!-- Link 3 - Upper arm link (Joint 3 in report - Elbow joint) -->
  <link name="link3">
    <visual>
      <geometry><box size="0.22 0.06 0.05"/></geometry>
      <origin xyz="0.11 0 0" rpy="0 0 0"/>
    </visual>
    <collision>
      <geometry><box size="0.22 0.06 0.05"/></geometry>
      <origin xyz="0.11 0 0" rpy="0 0 0"/>
    </collision>
    <inertial>
      <origin xyz="0.11 0 0" rpy="0 0 0"/>
      <mass value="0.6"/>
      <inertia ixx="0.004" ixy="0" ixz="0" iyy="0.012" iyz="0" izz="0.014"/>
    </inertial>
  </link>

  <!-- Link 4 - Forearm link (Joint 2 in report) -->
  <link name="link4">
    <visual>
      <geometry><box size="0.18 0.05 0.04"/></geometry>
      <origin xyz="0.09 0 0" rpy="0 0 0"/>
    </visual>
    <collision>
      <geometry><box size="0.18 0.05 0.04"/></geometry>
      <origin xyz="0.09 0 0" rpy="0 0 0"/>
    </collision>
    <inertial>
      <origin xyz="0.09 0 0" rpy="0 0 0"/>
      <mass value="0.4"/>
      <inertia ixx="0.002" ixy="0" ixz="0" iyy="0.008" iyz="0" izz="0.009"/>
    </inertial>
  </link>

  <!-- Link 5 - Wrist link (Joint 1 in report - Wrist joint with 360° rotation) -->
  <link name="link5">
    <visual>
      <geometry><cylinder radius="0.03" length="0.08"/></geometry>
      <origin xyz="0.04 0 0" rpy="0 1.5708 0"/>
    </visual>
    <collision>
      <geometry><cylinder radius="0.03" length="0.08"/></geometry>
      <origin xyz="0.04 0 0" rpy="0 1.5708 0"/>
    </collision>
    <inertial>
      <origin xyz="0.04 0 0" rpy="0 0 0"/>
      <mass value="0.3"/>
      <inertia ixx="0.001" ixy="0" ixz="0" iyy="0.003" iyz="0" izz="0.003"/>
    </inertial>
  </link>

  <!-- Link 6 - Gripper mounting plate -->
  <link name="link6">
    <visual>
      <geometry><box size="0.06 0.08 0.02"/></geometry>
      <origin xyz="0.03 0 0" rpy="0 0 0"/>
    </visual>
    <collision>
      <geometry><box size="0.06 0.08 0.02"/></geometry>
      <origin xyz="0.03 0 0" rpy="0 0 0"/>
    </collision>
    <inertial>
      <origin xyz="0.03 0 0" rpy="0 0 0"/>
      <mass value="0.2"/>
      <inertia ixx="0.0008" ixy="0" ixz="0" iyy="0.0015" iyz="0" izz="0.002"/>
    </inertial>
  </link>

  <!-- End Effector Link - Gripper -->
  <link name="end_effector_link">
    <visual>
      <geometry><box size="0.04 0.06 0.08"/></geometry>
      <origin xyz="0.02 0 0.04" rpy="0 0 0"/>
    </visual>
    <collision>
      <geometry><box size="0.04 0.06 0.08"/></geometry>
      <origin xyz="0.02 0 0.04" rpy="0 0 0"/>
    </collision>
    <inertial>
      <origin xyz="0.02 0 0.04" rpy="0 0 0"/>
      <mass value="0.15"/>
      <inertia ixx="0.0005" ixy="0" ixz="0" iyy="0.0008" iyz="0" izz="0.0008"/>
    </inertial>
  </link>

  <!-- Fixed joint from world to base -->
  <joint name="world_to_base_joint" type="fixed">
    <parent link="world"/>
    <child link="base_link"/>
    <origin xyz="0 0 0" rpy="0 0 0"/>
  </joint>

  <!-- Joint 1 - Base rotation (360° rotation) -->
  <joint name="joint1" type="revolute">
    <parent link="base_link"/>
    <child link="link1"/>
    <origin xyz="0 0 0.12" rpy="0 0 0"/>
    <axis xyz="0 0 1"/>
    <limit lower="-6.28" upper="6.28" velocity="1.0" effort="111.0"/>
    <safety_controller k_velocity="0.1" k_position="0.1"/>
    <dynamics damping="0.2" friction="0.3"/>
    <hardware_interface>
      <command_interface name="position"/>
      <state_interface name="position"/>
      <state_interface name="velocity"/>
    </hardware_interface>
  </joint>

  <!-- Joint 2 - Shoulder joint (35° range) -->
  <joint name="joint2" type="revolute">
    <parent link="link1"/>
    <child link="link2"/>
    <origin xyz="0 0 0.08" rpy="0 0 0"/>
    <axis xyz="0 1 0"/>
    <limit lower="-0.61" upper="0.61" velocity="1.0" effort="60.0"/>
    <safety_controller k_velocity="0.1" k_position="0.1"/>
    <dynamics damping="0.15" friction="0.2"/>
    <hardware_interface>
      <command_interface name="position"/>
      <state_interface name="position"/>
      <state_interface name="velocity"/>
    </hardware_interface>
  </joint>

  <!-- Joint 3 - Elbow joint (100° range) -->
  <joint name="joint3" type="revolute">
    <parent link="link2"/>
    <child link="link3"/>
    <origin xyz="0.25 0 0" rpy="0 0 0"/>
    <axis xyz="0 1 0"/>
    <limit lower="-1.75" upper="1.75" velocity="1.0" effort="30.0"/>
    <safety_controller k_velocity="0.1" k_position="0.1"/>
    <dynamics damping="0.1" friction="0.15"/>
    <hardware_interface>
      <command_interface name="position"/>
      <state_interface name="position"/>
      <state_interface name="velocity"/>
    </hardware_interface>
  </joint>

  <!-- Joint 4 - Forearm joint (75° range) -->
  <joint name="joint4" type="revolute">
    <parent link="link3"/>
    <child link="link4"/>
    <origin xyz="0.22 0 0" rpy="0 0 0"/>
    <axis xyz="0 1 0"/>
    <limit lower="-1.31" upper="1.31" velocity="1.0" effort="30.0"/>
    <safety_controller k_velocity="0.1" k_position="0.1"/>
    <dynamics damping="0.1" friction="0.1"/>
    <hardware_interface>
      <command_interface name="position"/>
      <state_interface name="position"/>
      <state_interface name="velocity"/>
    </hardware_interface>
  </joint>

  <!-- Joint 5 - Wrist rotation (360° rotation) -->
  <joint name="joint5" type="revolute">
    <parent link="link4"/>
    <child link="link5"/>
    <origin xyz="0.18 0 0" rpy="0 0 0"/>
    <axis xyz="1 0 0"/>
    <limit lower="-6.28" upper="6.28" velocity="1.0" effort="30.0"/>
    <safety_controller k_velocity="0.1" k_position="0.1"/>
    <dynamics damping="0.05" friction="0.05"/>
    <hardware_interface>
      <command_interface name="position"/>
      <state_interface name="position"/>
      <state_interface name="velocity"/>
    </hardware_interface>
  </joint>

  <!-- Joint 6 - Gripper mounting (fixed) -->
  <joint name="joint6" type="fixed">
    <parent link="link5"/>
    <child link="link6"/>
    <origin xyz="0.08 0 0" rpy="0 0 0"/>
  </joint>

  <!-- Joint from gripper mount to end effector -->
  <joint name="joint6_to_end_effector" type="fixed">
    <parent link="link6"/>
    <child link="end_effector_link"/>
    <origin xyz="0.06 0 0" rpy="0 0 0"/>
  </joint>

  <!-- ros2_control Configuration -->
  <ros2_control name="PegasusArm" type="system">
    <hardware>
      <plugin>mock_components/GenericSystem</plugin>
      <param name="example_param">example_value</param>
    </hardware>
    <joint name="joint1">
      <command_interface name="position">
        <param name="min">-6.28</param>
        <param name="max"> 6.28</param>
      </command_interface>
      <state_interface name="position"/>
      <state_interface name="velocity"/>
    </joint>
    <joint name="joint2">
      <command_interface name="position">
        <param name="min">-0.61</param>
        <param name="max"> 0.61</param>
      </command_interface>
      <state_interface name="position"/>
      <state_interface name="velocity"/>
    </joint>
    <joint name="joint3">
      <command_interface name="position">
        <param name="min">-1.75</param>
        <param name="max"> 1.75</param>
      </command_interface>
      <state_interface name="position"/>
      <state_interface name="velocity"/>
    </joint>
    <joint name="joint4">
      <command_interface name="position">
        <param name="min">-1.31</param>
        <param name="max"> 1.31</param>
      </command_interface>
      <state_interface name="position"/>
      <state_interface name="velocity"/>
    </joint>
    <joint name="joint5">
      <command_interface name="position">
        <param name="min">-6.28</param>
        <param name="max"> 6.28</param>
      </command_interface>
      <state_interface name="position"/>
      <state_interface name="velocity"/>
    </joint>
  </ros2_control>

  <!-- Gazebo-specific tags -->
  <gazebo>
    <plugin name="gazebo_ros_control" filename="libgazebo_ros_control.so">
      <robotNamespace>/pegasus</robotNamespace>
    </plugin>
  </gazebo>

  <!-- Transmissions for ros2_control -->
  <transmission name="joint1_trans">
    <type>transmission_interface/SimpleTransmission</type>
    <joint name="joint1">
      <hardwareInterface>hardware_interface/PositionJointInterface</hardwareInterface>
    </joint>
    <actuator name="joint1_motor">
      <mechanicalReduction>3.7</mechanicalReduction>
    </actuator>
  </transmission>
  
  <transmission name="joint2_trans">
    <type>transmission_interface/SimpleTransmission</type>
    <joint name="joint2">
      <hardwareInterface>hardware_interface/PositionJointInterface</hardwareInterface>
    </joint>
    <actuator name="joint2_motor">
      <mechanicalReduction>2.0</mechanicalReduction>
    </actuator>
  </transmission>
  
  <transmission name="joint3_trans">
    <type>transmission_interface/SimpleTransmission</type>
    <joint name="joint3">
      <hardwareInterface>hardware_interface/PositionJointInterface</hardwareInterface>
    </joint>
    <actuator name="joint3_motor">
      <mechanicalReduction>1</mechanicalReduction>
    </actuator>
  </transmission>
  
  <transmission name="joint4_trans">
    <type>transmission_interface/SimpleTransmission</type>
    <joint name="joint4">
      <hardwareInterface>hardware_interface/PositionJointInterface</hardwareInterface>
    </joint>
    <actuator name="joint4_motor">
      <mechanicalReduction>1</mechanicalReduction>
    </actuator>
  </transmission>
  
  <transmission name="joint5_trans">
    <type>transmission_interface/SimpleTransmission</type>
    <joint name="joint5">
      <hardwareInterface>hardware_interface/PositionJointInterface</hardwareInterface>
    </joint>
    <actuator name="joint5_motor">
      <mechanicalReduction>1</mechanicalReduction>
    </actuator>
  </transmission>

</robot>